Workbook

Sheet Summary
A1: Curvy project status
A2: Snapshot taken 2026-10-27. Counts below are live formulas over the Tracker sheet - change a Status there and they update.
A4: Area | B4: Done | C4: In Progress | D4: Not Started | E4: Deferred | F4: Total | G4: % done
A5: Foundation | B5: =COUNTIFS(Tracker!$B$2:$B$500,$A5,Tracker!$D$2:$D$500,B$4) | C5: =COUNTIFS(Tracker!$B$2:$B$500,$A5,Tracker!$D$2:$D$500,C$4) | D5: =COUNTIFS(Tracker!$B$2:$B$500,$A5,Tracker!$D$2:$D$500,D$4) | E5: =COUNTIFS(Tracker!$B$2:$B$500,$A5,Tracker!$D$2:$D$500,E$4) | F5: =SUM(B5:E5) | G5: =IF(F5=0,0,B5/F5)
A6: Document & graph | B6: =COUNTIFS(Tracker!$B$2:$B$500,$A6,Tracker!$D$2:$D$500,B$4) | C6: =COUNTIFS(Tracker!$B$2:$B$500,$A6,Tracker!$D$2:$D$500,C$4) | D6: =COUNTIFS(Tracker!$B$2:$B$500,$A6,Tracker!$D$2:$D$500,D$4) | E6: =COUNTIFS(Tracker!$B$2:$B$500,$A6,Tracker!$D$2:$D$500,E$4) | F6: =SUM(B6:E6) | G6: =IF(F6=0,0,B6/F6)
A7: Path & appearance nodes | B7: =COUNTIFS(Tracker!$B$2:$B$500,$A7,Tracker!$D$2:$D$500,B$4) | C7: =COUNTIFS(Tracker!$B$2:$B$500,$A7,Tracker!$D$2:$D$500,C$4) | D7: =COUNTIFS(Tracker!$B$2:$B$500,$A7,Tracker!$D$2:$D$500,D$4) | E7: =COUNTIFS(Tracker!$B$2:$B$500,$A7,Tracker!$D$2:$D$500,E$4) | F7: =SUM(B7:E7) | G7: =IF(F7=0,0,B7/F7)
A8: Animation & expressions | B8: =COUNTIFS(Tracker!$B$2:$B$500,$A8,Tracker!$D$2:$D$500,B$4) | C8: =COUNTIFS(Tracker!$B$2:$B$500,$A8,Tracker!$D$2:$D$500,C$4) | D8: =COUNTIFS(Tracker!$B$2:$B$500,$A8,Tracker!$D$2:$D$500,D$4) | E8: =COUNTIFS(Tracker!$B$2:$B$500,$A8,Tracker!$D$2:$D$500,E$4) | F8: =SUM(B8:E8) | G8: =IF(F8=0,0,B8/F8)
A9: Graph dock & panels | B9: =COUNTIFS(Tracker!$B$2:$B$500,$A9,Tracker!$D$2:$D$500,B$4) | C9: =COUNTIFS(Tracker!$B$2:$B$500,$A9,Tracker!$D$2:$D$500,C$4) | D9: =COUNTIFS(Tracker!$B$2:$B$500,$A9,Tracker!$D$2:$D$500,D$4) | E9: =COUNTIFS(Tracker!$B$2:$B$500,$A9,Tracker!$D$2:$D$500,E$4) | F9: =SUM(B9:E9) | G9: =IF(F9=0,0,B9/F9)
A10: Workspace & rings | B10: =COUNTIFS(Tracker!$B$2:$B$500,$A10,Tracker!$D$2:$D$500,B$4) | C10: =COUNTIFS(Tracker!$B$2:$B$500,$A10,Tracker!$D$2:$D$500,C$4) | D10: =COUNTIFS(Tracker!$B$2:$B$500,$A10,Tracker!$D$2:$D$500,D$4) | E10: =COUNTIFS(Tracker!$B$2:$B$500,$A10,Tracker!$D$2:$D$500,E$4) | F10: =SUM(B10:E10) | G10: =IF(F10=0,0,B10/F10)
A11: Pen & input | B11: =COUNTIFS(Tracker!$B$2:$B$500,$A11,Tracker!$D$2:$D$500,B$4) | C11: =COUNTIFS(Tracker!$B$2:$B$500,$A11,Tracker!$D$2:$D$500,C$4) | D11: =COUNTIFS(Tracker!$B$2:$B$500,$A11,Tracker!$D$2:$D$500,D$4) | E11: =COUNTIFS(Tracker!$B$2:$B$500,$A11,Tracker!$D$2:$D$500,E$4) | F11: =SUM(B11:E11) | G11: =IF(F11=0,0,B11/F11)
A12: Tools & cards | B12: =COUNTIFS(Tracker!$B$2:$B$500,$A12,Tracker!$D$2:$D$500,B$4) | C12: =COUNTIFS(Tracker!$B$2:$B$500,$A12,Tracker!$D$2:$D$500,C$4) | D12: =COUNTIFS(Tracker!$B$2:$B$500,$A12,Tracker!$D$2:$D$500,D$4) | E12: =COUNTIFS(Tracker!$B$2:$B$500,$A12,Tracker!$D$2:$D$500,E$4) | F12: =SUM(B12:E12) | G12: =IF(F12=0,0,B12/F12)
A13: Settings & themes | B13: =COUNTIFS(Tracker!$B$2:$B$500,$A13,Tracker!$D$2:$D$500,B$4) | C13: =COUNTIFS(Tracker!$B$2:$B$500,$A13,Tracker!$D$2:$D$500,C$4) | D13: =COUNTIFS(Tracker!$B$2:$B$500,$A13,Tracker!$D$2:$D$500,D$4) | E13: =COUNTIFS(Tracker!$B$2:$B$500,$A13,Tracker!$D$2:$D$500,E$4) | F13: =SUM(B13:E13) | G13: =IF(F13=0,0,B13/F13)
A14: Mockups & design | B14: =COUNTIFS(Tracker!$B$2:$B$500,$A14,Tracker!$D$2:$D$500,B$4) | C14: =COUNTIFS(Tracker!$B$2:$B$500,$A14,Tracker!$D$2:$D$500,C$4) | D14: =COUNTIFS(Tracker!$B$2:$B$500,$A14,Tracker!$D$2:$D$500,D$4) | E14: =COUNTIFS(Tracker!$B$2:$B$500,$A14,Tracker!$D$2:$D$500,E$4) | F14: =SUM(B14:E14) | G14: =IF(F14=0,0,B14/F14)
A15: Export & files | B15: =COUNTIFS(Tracker!$B$2:$B$500,$A15,Tracker!$D$2:$D$500,B$4) | C15: =COUNTIFS(Tracker!$B$2:$B$500,$A15,Tracker!$D$2:$D$500,C$4) | D15: =COUNTIFS(Tracker!$B$2:$B$500,$A15,Tracker!$D$2:$D$500,D$4) | E15: =COUNTIFS(Tracker!$B$2:$B$500,$A15,Tracker!$D$2:$D$500,E$4) | F15: =SUM(B15:E15) | G15: =IF(F15=0,0,B15/F15)
A16: Planned | B16: =COUNTIFS(Tracker!$B$2:$B$500,$A16,Tracker!$D$2:$D$500,B$4) | C16: =COUNTIFS(Tracker!$B$2:$B$500,$A16,Tracker!$D$2:$D$500,C$4) | D16: =COUNTIFS(Tracker!$B$2:$B$500,$A16,Tracker!$D$2:$D$500,D$4) | E16: =COUNTIFS(Tracker!$B$2:$B$500,$A16,Tracker!$D$2:$D$500,E$4) | F16: =SUM(B16:E16) | G16: =IF(F16=0,0,B16/F16)
A17: All areas | B17: =SUM(B5:B16) | C17: =SUM(C5:C16) | D17: =SUM(D5:D16) | E17: =SUM(E5:E16) | F17: =SUM(F5:F16) | G17: =IF(F17=0,0,B17/F17)
A19: Legend
A20: Done | B20: Built, tested, and you have confirmed it works.
A21: In Progress | B21: Started, or built and tested but not yet confirmed live.
A22: Not Started | B22: Nothing built yet (a mockup or notes may exist).
A23: Deferred | B23: Deliberately parked - the plan keeps it for later.

Sheet Tracker
A1: ID | B1: Area | C1: Item | D1: Status | E1: Suggested priority | F1: Notes / what is left | G1: Verified
A2: F-01 | B2: Foundation | C2: Sketch demo ported to src/ + include/curvy (namespace curvy), C++17 | D2: Done | F2: Build via VS vcvars64 + cmake preset x64-release. | G2: From docs/memory; not re-checked
A3: F-02 | B3: Foundation | C3: jitnodes + newui as submodules; own asmjit build for jitnodes | D3: Done | F3: Submodule bumps are committed by the user. 2026-10-27: jitnodes 82dc600 (fx nodes) used C++20 <bit>; fixed upstream in e524be1 (C++17). Parent bump uncommitted. | G3: From docs/memory; not re-checked
A4: F-03 | B4: Foundation | C4: Google Test suite | D4: Done | F4: 320 tests at last run; jitnodes 97. | G4: Built + tested; not yet tried live
A5: F-04 | B5: Foundation | C5: Headless checks: --check, --check-tools, --check-workspace | D5: Done | F5: All exit 0 at last run. | G5: Built + tested; not yet tried live
A6: F-05 | B6: Foundation | C6: GUI test suite (tests/gui, real input) | D6: Done | E6: Medium | F6: 52 tests (2026-10-27): 48 at 2026-10-25 + 4 transform-row tests; only the GraphDock class (11) rerun since. | G6: Built + tested; not yet tried live
A7: F-06 | B7: Foundation | C7: Port the original demo's --check-tools / gui tests | D7: Not Started | E7: Low | F7: Pending item from the port. | G7: From docs/memory; not re-checked
A8: F-07 | B8: Foundation | C8: reflectgen .venv must be recreated on a fresh clone | D8: Not Started | E8: Low | G8: From docs/memory; not re-checked
A9: DG-01 | B9: Document & graph | C9: GraphDocument owns the jitnodes Network; SketchDocument derives from it | D9: Done | F9: Single shared UndoStack; graph edits are snapshot closures. | G9: Built + tested; not yet tried live
A10: DG-02 | B10: Document & graph | C10: Live shapes + SVG round trip (graph embedded in a namespaced SVG element) | D10: Done | G10: Built + tested; not yet tried live
A11: DG-03 | B11: Document & graph | C11: Objects as pure views of nodes (node is the only truth) | D11: Done | E11: High | F11: Stage 3 done 2026-10-25: selection bounds + frame measured on placedOutline() (falls back to the object for driven or mid-drag objects). Left: frameAngle/matrix still the object's; path copy still held (next: geometry() becomes a cache refreshed from the node, then DG-05). Perf (2000 objects): frame+bounds 0.5 ms at rest, 0.15 ms mid-drag; placedOutline cached per object, findById indexed; timeline step 23 -> 1.5 ms after jitnodes fixes (setTime keeps a cached list of animated nodes). Option 3 chosen: full node-truth redesign, plan in docs/dg03-node-truth.md. S1 done (paintWarp on the transform node; frameAngle stays outside the graph: it diverges from the node rotation once shear appears). S2 done: every placement edit goes through SketchDocument::placeObjects (transform node written first, object refreshed, outline cache seeded) with commitPlacement as the undo step; a whole-graph snapshot measured 135 ms at 2000 objects so undo restores the touched nodes' numbers instead (drag step 3.8 ms, commit 4 ms, undo 5 ms). S3 done for outline edits: setObjectOutline/syncObject rewrite the shape node's curve at once (direct select, live shape handles, reverse, simplify, join, redefine symbol, text warp, warp; undo/redo per object). S4a done: outline/placement/text/symbol/image mutators of SketchObject are private (SketchDocument friend; SketchObject::Prototype for objects not in a document yet), new document calls warpObjects / setObjectText / changeSelectionText on a TextState; writePathNodes removed; tests converted. S5 done for .skb (DG-05). S6 done: nodeRevision replaced by boundToNodes()/everBound() (every outline edit clears it; geometryRevision is only the outline-cache version). Kept on purpose: syncPathNodes and bindLoadedNode (add building chains per object is quadratic in batches or needs the binder rewritten, and SVG files still match outlines to embedded nodes); GeometryState stays as the undo payload. DG-03 is finished apart from those. | G11: Built + tested: 332 curvyTests, checks pass, GUI 48 pass; behaviour unchanged
A12: DG-04 | B12: Document & graph | C12: Layers / groups as subnets | D12: In Progress | E12: High | F12: Step 3/4 of the node-architecture plan. 2026-10-28: S0 spike done -> option B (structure nodes in the flat root); DG-07 later removed the subnet undo cost, so option A is open again if wanted. 2026-10-28: option A (containment) chosen. S1 done: NodeRef{scope,id}, GraphDocument scopes/NodeRef edit API, SketchObject::graphScope; root-scope NodeId shortcuts kept; callers move to NodeRef in S2/S3. S2 done 2026-10-28: curvySubnet node (role/visible/locked/opacity/blend/clip + promoted placement numbers), SketchDocument::scopeMatrix/worldOf/transformRefOf, sync loops and caches per scope (a hand-built group moves its member, undo/redo works); transformNodeOf/selection/graph dock still root-only until S3/S5. S2.5 done 2026-10-28: membership accessors on SketchDocument (groupsOf/outermostGroupOf/isGrouped/inGroup/layerOf/setGroupsOf/setLayerOf) in front of SketchObject::groups()/layer(); all production sites outside the serializers (writeObject, SVG readers, sketchbin) use them. S3a done 2026-10-28: groups are real subnets by containment, derived from the group ids (syncGroupScopes/pruneGroupScopes in changed(), curvySubnet groupId param; chains copied so expressions/keys survive; SVG data-graph-scope and .skb scope paths). S5 (scoped selection) done 2026-10-28: hitTestNode/selectedNodes/setSelectedNodes return NodeRef, pivot code and the graph dock (rows, detail box, links, edits) work on NodeRef so grouped objects show and edit; enter/exit-group view not built. Next: S3b flip the carrier (drop groups_/groupProps_, read from subnets). Plan: docs/dg04-layers-subnets.md. Idea logged: packed-paths node (Houdini packed geometry). | G12: S5 built + tested: new test NodeSelection.GroupedObjectsAreSelectedAndPickedByTheirScopedNode; ctest 2086 pass, --check/--check-tools/--check-workspace exit 0; GUI suite not rerun
A13: DG-05 | B13: Document & graph | C13: Graph saved in .skb | D13: Done | E13: Medium | F13: 2026-10-25: .skb version 4 stores the graph (GRPH chunk: graph text + each object shape node id) and leaves out the outline of every object its node holds (SketchDocument::pathHeldByNode); load reads the graph first (scratch network validates it) and builds those outlines from the node curve under the saved placement. Text keeps its outline; v1-3 files still load. Costs: quadratics come back as cubics, outlines to a float step, file grows ~450 B/object before gzip. SVG already embedded the graph. | G13: Built + tested: 330 curvyTests, checks pass, GUI 44 pass; not tried by hand
A14: DG-06 | B14: Document & graph | C14: Drag-to-connect rows in the graph | D14: Not Started | E14: Medium | G14: From docs/memory; not re-checked
A15: PN-01 | B15: Path & appearance nodes | C15: curvyPath / Text / Symbol / Image nodes | D15: Done | F15: Outline held in geometry param `curve`. | G15: Built + tested; not yet tried live
A16: PN-02 | B16: Path & appearance nodes | C16: Cubic primitives in jitnodes (bezier path geometry) | D16: Done | F16: jitnodes change was uncommitted at last note. | G16: Built + tested; not yet tried live
A17: PN-03 | B17: Path & appearance nodes | C17: Geometry-valued node parameters | D17: Done | G17: Built + tested; not yet tried live
A18: PN-04 | B18: Path & appearance nodes | C18: Fill / Stroke / Effect appearance nodes | D18: Done | G18: Built + tested; not yet tried live
A19: PN-05 | B19: Path & appearance nodes | C19: Transform node (translate/rotation/scale/shear/pivot) + parents | D19: Done | G19: Built + tested; not yet tried live
A20: PN-06 | B20: Path & appearance nodes | C20: Tag node + Move Points node (driven objects) | D20: Done | F20: Box now on ParamGrid: kind/operation are Choice rows, every/offset scrub. Tag name is fixed 'tag1'; no naming/switching or marquee tagging yet. | G20: Built + tested; not yet tried live
A21: PN-07 | B21: Path & appearance nodes | C21: Point gradients (Points paint kind) | D21: Done | F21: PDF/other viewers see the first colour only. | G21: Built + tested; not yet tried live
A22: PN-08 | B22: Path & appearance nodes | C22: Perspective-warp paints | D22: In Progress | E22: Low | F22: Canvas only; SVG/PDF export still unwarped. | G22: Built + tested; not yet tried live
A23: PN-09 | B23: Path & appearance nodes | C23: Colour / swatch nodes; instance nodes for symbols | D23: Not Started | E23: Medium | G23: From docs/memory; not re-checked
A24: PN-10 | B24: Path & appearance nodes | C24: Deform-along-path node (skeletal strokes) | D24: Not Started | E24: Low | G24: From docs/memory; not re-checked
A25: AN-01 | B25: Animation & expressions | C25: Property expressions (=expr, time/frame) | D25: Done | F25: ExpressionField in the graph dock. | G25: Built + tested; not yet tried live
A26: AN-02 | B26: Animation & expressions | C26: TimelineBar (transport strip, View ring slot M) | D26: Done | G26: Built + tested; not yet tried live
A27: AN-03 | B27: Animation & expressions | C27: Keyframes in parameter fields (Ctrl+K, diamond, edits write keys) | D27: In Progress | F27: Built + tested; linear keys only. | G27: Built + tested; not yet tried live
A28: AN-04 | B28: Animation & expressions | C28: Easing picker / typed keys (jitnodes has no bezier easing) | D28: Not Started | E28: Medium | G28: From docs/memory; not re-checked
A29: AN-05 | B29: Animation & expressions | C29: Ruler, keyed rows and dopesheet | D29: Deferred | E29: Medium | F29: User chose to hold; mockup is docs/mockups/animation.html. | G29: Mockup only (headless Chrome); not hand-tested
A30: AN-06 | B30: Animation & expressions | C30: Frame range + fps as saved document settings | D30: Not Started | E30: Medium | G30: From docs/memory; not re-checked
A31: AN-07 | B31: Animation & expressions | C31: Timeline/Play menu item and key | D31: Not Started | E31: Low | G31: From docs/memory; not re-checked
A32: AN-08 | B32: Animation & expressions | C32: Rig: bones, IK, skinning, weight painting | D32: Not Started | E32: Low | F32: Mockup docs/mockups/rig.html. | G32: Mockup only (headless Chrome); not hand-tested
A33: AN-09 | B33: Animation & expressions | C33: Animated export: one EXR per frame with AOV layers | D33: Not Started | E33: Low | F33: Blend2D is 8-bit, so a float raster path is needed. | G33: From docs/memory; not re-checked
A34: GD-01 | B34: Graph dock & panels | C34: Graph tree (Document / Flow views, filter, icons, chips) | D34: Done | G34: Built + tested; not yet tried live
A35: GD-02 | B35: Graph dock & panels | C35: Parameter box painted by ParamGrid (one editor at a time) | D35: Done | F35: Builds, unit + GUI tests pass; Esc/Ctrl+K fixed (newui key codes); NumberScrubber/ParamGrid use Delegates; Choice rows added; not hand-tried. | G35: Built + tested; not yet tried live
A36: GD-03 | B36: Graph dock & panels | C36: Key diamond per number row | D36: In Progress | E36: Medium | F36: Painted and clickable; not hand-tested. | G36: Built + tested; not yet tried live
A37: GD-04 | B37: Graph dock & panels | C37: Fix `+=` lambdas capturing this that can fire after destruction (GraphDock, DockController) | D37: Done | E37: High | F37: 2026-10-25: GraphDock and DockController handlers go through guarded() (include/curvy/aliveguard.h) with an alive_ flag cleared in the destructor, as TimelineBar does. Removing connections instead was considered; the flag is safe whatever the view teardown order. Superseded 2026-10-27 by GD-07: the alive_ flag is replaced by newui::Connections. | G37: Built + tested; not yet tried live
A38: GD-05 | B38: Graph dock & panels | C38: Context-sensitive property dock (Colour / Stroke / Opacity boxes) | D38: Done | G38: Built + tested; not yet tried live
A39: GD-06 | B39: Graph dock & panels | C39: Live-shape / Text / gradient property boxes | D39: Not Started | E39: Medium | G39: From docs/memory; not re-checked
A40: WR-01 | B40: Workspace & rings | C40: WorkspaceController / Model, empty-workspace start, docks | D40: Done | G40: Built + tested; not yet tried live
...

Sheet Notes
A1: How to use
A2: Update this tracker after each task that gets implemented: set the item's Status, Notes and Verified, add a row for new work, and refresh the test counts under Known limits. (Also recorded in CLAUDE.md.)
A3: Tracker sheet: pick a Status from the dropdown - the cell recolours itself (green / yellow / red / grey).
A4: Add a row at the bottom and it is counted automatically (the Summary reads down to row 500). Use an existing Area name, or add a new area row on the Summary sheet.
A5: Use the filter arrows on the header row to look at, say, only Not Started + High priority.
A6: How this was built
A7: Statuses come from the project memory notes, docs/design.md and docs/ui-design.md, and this session's work. Nothing was re-run to build the sheet except the figures quoted below.
A8: The Verified column says how sure each status is: 'User-verified' (you confirmed it), 'Built + tested; not yet tried live' (tests pass, you have not tried it), 'Mockup only' (headless Chrome tests), 'From docs/memory; not re-checked'.
A9: Suggested priority is only a suggestion - overwrite freely.
A10: Known limits
A11: Test counts at snapshot time (2026-10-27): curvyTests 335 pass (1 skipped); GUI suite 55 pass (full run 2026-10-27); jitnodesTests 98 at 2026-10-25, not rerun; newui Delegate + Connections tests 32 pass (2026-10-27); --check, --check-tools, --check-workspace exit 0. These are typed-in numbers, not formulas.
A12: This is a snapshot: it will not update itself. Ask for a refresh at the end of a work session.
